Workbook

Sheet Hoja2
A2: 17993082
A3: 13019098
A4: 10980475
A5: 10235507
A6: 14702163
A7: 15523553
A8: 11471954
A9: 12379177
A10: 11464736
A11: 11446874
A12: 13186732
A13: 12168387
... A28: 14937506

Sheet Hoja1
A1: CU | B1: CODUNICO | C1: Documento | D1: Nombre Cliente | E1: Analista | F1: Calificación | G1: Observaciones | H1: nueva calificación | I1: SCORE | J1: VALOR | K1: RANGO | L1: Max Fecha alerta
A2: 17993082 | B2: 17993082 | C2: 72657054 | D2: DIAZ RUBIO CARLOS MARTIN ALEJANDRO | E2: Michael Pinillos | F2: SIN RIESGO | G2: ROS reciente | H2: Con riesgo | I2: 0.9979048 | J2: 1 | K2: 1 | L2: =VLOOKUP(B2,Hoja3!$B$2:$C$30,2,FALSE) -> 2026-06
A3: 13019098 | B3: 13019098 | C3: 9663930 | D3: CORTEZ GALVEZ RUDY MADELEINE | E3: Carolina Aranda | F3: CON RIESGO | G3: ampliación de ROS | H3: Con riesgo | I3: 0.9978382 | J3: 2 | K3: 1 | L3: =VLOOKUP(B3,Hoja3!$B$2:$C$30,2,FALSE) -> 2025-07
A4: 14392145 | B4: 14392145 | C4: 43164623 | D4: ARANDA ROMERO MANUEL ROGER | E4: David Solano | F4: Con Riesgo | G4: Ferretero | H4: Con riesgo | I4: 0.9974474 | J4: 3 | K4: 1
A5: 15085930 | B5: 15085930 | C5: 73873021 | D5: RAMOS CASTAÑEDA MARY JHOSSELYN | E5: Lorena Hidalgo | F5: Sin riesgo | G5: Comunero de Llacuabamba | H5: Sin riesgo | I5: 0.997156 | J5: 4 | K5: 1
A6: 10980475 | B6: 10980475 | C6: 43589523 | D6: PEREZ CUZCANO EVELYN MARLENE | E6: Michael Pinillos | F6: SIN RIESGO | G6: Reportado en el último semestre | H6: Con riesgo | I6: 0.9968352 | J6: 5 | K6: 1 | L6: =VLOOKUP(B6,Hoja3!$B$2:$C$30,2,FALSE) -> 2026-03
A7: 16524108 | B7: 16524108 | C7: 19434571 | D7: ALVAREZ ASPIROS FIDELA ROSA | E7: Lorena Hidalgo | F7: Con riesgo | H7: Con riesgo | I7: 0.99667126 | J7: 6 | K7: 1
A8: 12171100 | B8: 12171100 | C8: 42568498 | D8: AYALA SANCHEZ ANIBAL JHON | E8: Alessander Montañez | F8: Sin Riesgo | H8: Sin riesgo | I8: 0.99658513 | J8: 7 | K8: 1
A9: 13148913 | B9: 13148913 | C9: 43713325 | D9: HENRIQUEZ VASQUEZ NEDER JOSE | E9: Juan Scudellari | F9: SIN RIESGO | H9: Sin riesgo | I9: 0.99658114 | J9: 8 | K9: 1
A10: 16040595 | B10: 16040595 | C10: 45863703 | D10: FLORES ESCALANTE BRAYAN LEONEL | E10: Juan Scudellari | F10: CON RIESGO | H10: Con riesgo | I10: 0.99650097 | J10: 9 | K10: 1
A11: 15216217 | B11: 15216217 | C11: 75385218 | D11: RODRIGUEZ PAREDES DEYSON MIGUEL | E11: Lorena Hidalgo | F11: Sin riesgo | G11: Comunero de Llacuabamba | H11: Sin riesgo | I11: 0.99638283 | J11: 10 | K11: 1
A12: 10235507 | B12: 10235507 | C12: 25132757 | D12: QUISPE LAURA ALEJO | E12: Angie Mendoza | F12: SIN RIESGO | G12: Reportado 202604 | H12: Con riesgo | I12: 0.9961641 | J12: 11 | K12: 1 | L12: =VLOOKUP(B12,Hoja3!$B$2:$C$30,2,FALSE) -> 2026-05
A13: 14702163 | B13: 14702163 | C13: 41234823 | D13: ALVAREZ PAITAMPOMA CHRISTIAN ROBERTO | E13: Juan Scudellari | F13: SIN RIESGO | G13: Reportado en los últimos 6 meses | H13: Con riesgo | I13: 0.9960377 | J13: 12 | K13: 1 | L13: =VLOOKUP(B13,Hoja3!$B$2:$C$30,2,FALSE) -> 2025-10
A14: 15523553 | B14: 15523553 | C14: 48480849 | D14: OLORTEGUI GUEVARA JOSEF ANTONIO | E14: Juan Scudellari | F14: SIN RIESGO | G14: Tiene caso en proceso | H14: Con riesgo | I14: 0.99600214 | J14: 13 | K14: 1 | L14: =VLOOKUP(B14,Hoja3!$B$2:$C$30,2,FALSE) -> 2026-03
A15: 16550769 | B15: 16550769 | C15: 45992241 | D15: BALLENA ARAUJO WALTER NICOLAS | E15: Lorena Hidalgo | F15: Con riesgo | H15: Con riesgo | I15: 0.9958781 | J15: 14 | K15: 1
A16: 14048264 | B16: 14048264 | C16: 48126120 | D16: ROJAS ANAMPA MAYKOL DENIS | E16: David Solano | F16: Sin Riesgo | G16: Comunero Llacuabamba | H16: Sin riesgo | I16: 0.99580365 | J16: 15 | K16: 2
A17: 11471954 | B17: 11471954 | C17: 44337189 | D17: ESPEJO HERRERA EDUARDO JOSE | E17: Alessander Montañez | F17: CON RIESGO | G17: CLIENTE EN COLA DE DESVINCULACION | H17: Con riesgo | I17: 0.9955226 | J17: 16 | K17: 2 | L17: =VLOOKUP(B17,Hoja3!$B$2:$C$30,2,FALSE) -> 2025-10
A18: 11816818 | B18: 11816818 | C18: 45474845 | D18: ZELADA YANTAS KAROLI JESMY | E18: Alessander Montañez | F18: Sin Riesgo | H18: Sin riesgo | I18: 0.9954964 | J18: 17 | K18: 2
A19: 10715430 | B19: 10715430 | C19: 24707752 | D19: CRUZ CASTAÑEDA CELIA MARY LUZ | E19: Angie Mendoza | F19: CON RIESGO | H19: Con riesgo | I19: 0.99548364 | J19: 18 | K19: 2
A20: 12799861 | B20: 12799861 | C20: 44792378 | D20: ORTIZ PINEDA JUAN ANTONIO | E20: Carolina Aranda | F20: CON RIESGO | G20: contraparte reportada | H20: Con riesgo | I20: 0.9953974 | J20: 19 | K20: 2
A21: 12379177 | B21: 12379177 | C21: 45039716 | D21: PEREZ QUISPE EFRAIN | E21: Michael Pinillos | F21: SIN RIESGO | G21: Cliente con caso en Investigación | H21: Con riesgo | I21: 0.9953484 | J21: 20 | K21: 2 | L21: =VLOOKUP(B21,Hoja3!$B$2:$C$30,2,FALSE) -> 2026-06
A22: 9403557 | B22: 9403557 | C22: 40194046 | D22: GONZALEZ DEL AGUILA LUIS DAVID | E22: Juan Scudellari | F22: CON RIESGO | H22: Con riesgo | I22: 0.99530584 | J22: 21 | K22: 2
A23: 10201670 | B23: 10201670 | C23: 41468927 | D23: DOMINGUEZ LOPEZ ISELA CARMEN | E23: Angie Mendoza | F23: SIN RIESGO | H23: Sin riesgo | I23: 0.9951905 | J23: 22 | K23: 2
A24: 14220569 | B24: 14220569 | C24: 76880862 | D24: QUISPE SANTOS JHENYFER PAOLA | E24: Michael Pinillos | F24: CON RIESGO | H24: Con riesgo | I24: 0.9951106 | J24: 23 | K24: 2
A25: 19934106 | B25: 19934106 | C25: 800962 | D25: PEREZ TAFUR DE LOPEZ MARIESTHER CAROLINA | E25: Michael Pinillos | F25: SIN RIESGO | H25: Sin riesgo | I25: 0.9950001 | J25: 24 | K25: 2
A26: 11464736 | B26: 11464736 | C26: 40903456 | D26: OYARCE VENAUTE SANDRA YOBANA | E26: Michael Pinillos | F26: SIN RIESGO | G26: Recientemente reportado | H26: Con riesgo | I26: 0.9949151 | J26: 25 | K26: 2 | L26: =VLOOKUP(B26,Hoja3!$B$2:$C$30,2,FALSE) -> 2025-10
A27: 11848931 | B27: 11848931 | C27: 45160276 | D27: LUNA MORALES JOSE LUIS | E27: Alessander Montañez | F27: CON RIESGO | H27: Con riesgo | I27: 0.9948985 | J27: 26 | K27: 2
A28: 11446874 | B28: 11446874 | C28: 45516204 | D28: HUAYNATE ALVARO POOL JOSHI | E28: Alessander Montañez | F28: CON RIESGO | G28: CLIENTE EN COLA DE DESVINCULACION | H28: Con riesgo | I28: 0.99481946 | J28: 27 | K28: 3 | L28: =VLOOKUP(B28,Hoja3!$B$2:$C$30,2,FALSE) -> 2026-06
A29: 12305875 | B29: 12305875 | C29: 45137638 | D29: MARGARIN CASTAÑEDA WALDY ELIFIO | E29: Alessander Montañez | F29: Sin Riesgo | H29: Sin riesgo | I29: 0.99480927 | J29: 28 | K29: 3
A30: 13186732 | B30: 13186732 | C30: 22098455 | D30: HUAMANI CACERES NIDIA BEATRIZ | E30: Carolina Aranda | F30: CON RIESGO | G30: ampliación de ROS | H30: Con riesgo | I30: 0.9946702 | J30: 29 | K30: 3 | L30: =VLOOKUP(B30,Hoja3!$B$2:$C$30,2,FALSE) -> 2025-07
A31: 10815398 | B31: 10815398 | C31: 42944338 | D31: HUAQUI RAMOS ROSI ALVINA | E31: Angie Mendoza | F31: CON RIESGO | H31: Con riesgo | I31: 0.99464095 | J31: 30 | K31: 3
A32: 13220742 | B32: 13220742 | C32: 19420648 | D32: MORILLO GUILLEN ALFONSO | E32: Carolina Aranda | F32: Sin Riesgo | G32: Comunero llacuabamba | H32: Sin riesgo | I32: 0.99454135 | J32: 31 | K32: 3
A33: 10978185 | B33: 10978185 | C33: 43543736 | D33: AVILES AVILA CHRISTIAN ENRIQUEZ | E33: Angie Mendoza | F33: SIN RIESGO | H33: Sin riesgo | I33: 0.9944825 | J33: 32 | K33: 3
A34: 10763695 | B34: 10763695 | C34: 41808068 | D34: ZACONETTY LOJA EDGAR ANTONIO | E34: Angie Mendoza | F34: CON RIESGO | H34: Con riesgo | I34: 0.99444807 | J34: 33 | K34: 3
A35: 18432108 | B35: 18432108 | C35: 71345537 | D35: PUMA YUCRA FELIX WILFREDO | E35: Michael Pinillos | F35: SIN RIESGO | H35: Sin riesgo | I35: 0.99442756 | J35: 34 | K35: 3
A36: 12168387 | B36: 12168387 | C36: 70477161 | D36: BAUTISTA FLORIAN JORGE JOEL | E36: Alessander Montañez | F36: Sin Riesgo | G36: Reportado en 2026-06 | H36: Con riesgo | I36: 0.9944022 | J36: 35 | K36: 3 | L36: =VLOOKUP(B36,Hoja3!$B$2:$C$30,2,FALSE) -> 2026-01
A37: 13198922 | B37: 13198922 | C37: 47259291 | D37: ACUÑA BOCANEGRA KARLA FIORELLY | E37: Carolina Aranda | F37: Sin Riesgo | G37: Comunero llacuabamba | H37: Sin riesgo | I37: 0.9943346 | J37: 36 | K37: 3
A38: 13142121 | B38: 13142121 | C38: 19419239 | D38: SAAVEDRA CASTAÑEDA HERNAN | E38: Carolina Aranda | F38: CON RIESGO | G38: Comunero llacuabamba que recibe ingresos relevantes de contraparte reportada en 2026 | H38: Con riesgo | I38: 0.9943334 | J38: 37 | K38: 3
A39: 20944140 | B39: 20944140 | C39: 20604544719 | D39: IBVC PERU S.A.C. | E39: Juan Scudellari | F39: SIN RIESGO | H39: Sin riesgo | I39: 0.9943032 | J39: 38 | K39: 3
A40: 13199373 | B40: 13199373 | C40: 19419299 | D40: VILLANUEVA SILVA ELIAS | E40: Michael Pinillos | F40: SIN RIESGO | G40: Cliente con caso en Investigación | H40: Con riesgo | I40: 0.9942849 | J40: 39 | K40: 4 | L40: =VLOOKUP(B40,Hoja3!$B$2:$C$30,2,FALSE) -> 2026-01
...

Sheet Hoja3
A1: codunico | B1: periodo
A2: # | B2: codunico | C2: periodo
A3: 1 | B3: 12168387 | C3: 2026-01
A4: 2 | B4: 9436194 | C4: 2025-12
A5: 3 | B5: 11851541 | C5: 2026-06
A6: 4 | B6: 11767818 | C6: 2025-10
A7: 5 | B7: 14937506 | C7: 2025-08
A8: 6 | B8: 13871357 | C8: 2025-09
A9: 7 | B9: 10235507 | C9: 2026-05
A10: 8 | B10: 13199373 | C10: 2026-01
A11: 9 | B11: 11464736 | C11: 2025-10
A12: 10 | B12: 16479861 | C12: 2026-02
A13: 11 | B13: 15458852 | C13: 2026-02
A14: 12 | B14: 15681866 | C14: 2026-05
... A30: 28 | B30: 10980475 | C30: 2026-03
